{
 "cells": [
  {
   "cell_type": "code",
   "execution_count": 2,
   "id": "c4064029-dc0e-46b8-a1b7-d9d6a98fd1a0",
   "metadata": {},
   "outputs": [
    {
     "name": "stdout",
     "output_type": "stream",
     "text": [
      "Collecting redis\n",
      "  Downloading redis-4.4.2-py3-none-any.whl (237 kB)\n",
      "     -------------------------------------- 237.8/237.8 kB 2.1 MB/s eta 0:00:00\n",
      "Requirement already satisfied: async-timeout>=4.0.2 in c:\\users\\user\\appdata\\roaming\\jupyterlab-desktop\\jlab_server\\lib\\site-packages (from redis) (4.0.2)\n",
      "Installing collected packages: redis\n",
      "Successfully installed redis-4.4.2\n"
     ]
    }
   ],
   "source": [
    "!pip install redis\n",
    "!sudo snap install redis"
   ]
  },
  {
   "cell_type": "code",
   "execution_count": 4,
   "id": "1aa1f52c-5fe2-4ab9-b966-a1bbf3f0f4b7",
   "metadata": {},
   "outputs": [],
   "source": [
    "import redis\n",
    "import concurrent.futures\n",
    "import pickle as pkl\n",
    "from loguru import logger"
   ]
  },
  {
   "cell_type": "code",
   "execution_count": 5,
   "id": "3c0262f2-0a8b-42ed-8365-9f97dbaa1006",
   "metadata": {},
   "outputs": [],
   "source": [
    "r = redis.Redis(host=\"127.0.0.1\", port=6379, db=1) \n",
    "\n",
    "def get_cache_on_key(key):\n",
    "    buff = r.get(key)\n",
    "    if buff:\n",
    "        return pkl.loads(buff)\n",
    "    else:\n",
    "        logger.info('Not found data in redis')"
   ]
  },
  {
   "cell_type": "code",
   "execution_count": 7,
   "id": "e3a67e6c-4445-4267-8c66-8fa052ca2312",
   "metadata": {},
   "outputs": [
    {
     "ename": "ConnectionError",
     "evalue": "Error 10061 connecting to 127.0.0.1:6379. Подключение не установлено, т.к. конечный компьютер отверг запрос на подключение.",
     "output_type": "error",
     "traceback": [
      "\u001b[1;31m---------------------------------------------------------------------------\u001b[0m",
      "\u001b[1;31mConnectionRefusedError\u001b[0m                    Traceback (most recent call last)",
      "File \u001b[1;32m~\\AppData\\Roaming\\jupyterlab-desktop\\jlab_server\\lib\\site-packages\\redis\\connection.py:624\u001b[0m, in \u001b[0;36mConnection.connect\u001b[1;34m(self)\u001b[0m\n\u001b[0;32m    623\u001b[0m \u001b[38;5;28;01mtry\u001b[39;00m:\n\u001b[1;32m--> 624\u001b[0m     sock \u001b[38;5;241m=\u001b[39m \u001b[38;5;28;43mself\u001b[39;49m\u001b[38;5;241;43m.\u001b[39;49m\u001b[43mretry\u001b[49m\u001b[38;5;241;43m.\u001b[39;49m\u001b[43mcall_with_retry\u001b[49m\u001b[43m(\u001b[49m\n\u001b[0;32m    625\u001b[0m \u001b[43m        \u001b[49m\u001b[38;5;28;43;01mlambda\u001b[39;49;00m\u001b[43m:\u001b[49m\u001b[43m \u001b[49m\u001b[38;5;28;43mself\u001b[39;49m\u001b[38;5;241;43m.\u001b[39;49m\u001b[43m_connect\u001b[49m\u001b[43m(\u001b[49m\u001b[43m)\u001b[49m\u001b[43m,\u001b[49m\u001b[43m \u001b[49m\u001b[38;5;28;43;01mlambda\u001b[39;49;00m\u001b[43m \u001b[49m\u001b[43merror\u001b[49m\u001b[43m:\u001b[49m\u001b[43m \u001b[49m\u001b[38;5;28;43mself\u001b[39;49m\u001b[38;5;241;43m.\u001b[39;49m\u001b[43mdisconnect\u001b[49m\u001b[43m(\u001b[49m\u001b[43merror\u001b[49m\u001b[43m)\u001b[49m\n\u001b[0;32m    626\u001b[0m \u001b[43m    \u001b[49m\u001b[43m)\u001b[49m\n\u001b[0;32m    627\u001b[0m \u001b[38;5;28;01mexcept\u001b[39;00m socket\u001b[38;5;241m.\u001b[39mtimeout:\n",
      "File \u001b[1;32m~\\AppData\\Roaming\\jupyterlab-desktop\\jlab_server\\lib\\site-packages\\redis\\retry.py:46\u001b[0m, in \u001b[0;36mRetry.call_with_retry\u001b[1;34m(self, do, fail)\u001b[0m\n\u001b[0;32m     45\u001b[0m \u001b[38;5;28;01mtry\u001b[39;00m:\n\u001b[1;32m---> 46\u001b[0m     \u001b[38;5;28;01mreturn\u001b[39;00m \u001b[43mdo\u001b[49m\u001b[43m(\u001b[49m\u001b[43m)\u001b[49m\n\u001b[0;32m     47\u001b[0m \u001b[38;5;28;01mexcept\u001b[39;00m \u001b[38;5;28mself\u001b[39m\u001b[38;5;241m.\u001b[39m_supported_errors \u001b[38;5;28;01mas\u001b[39;00m error:\n",
      "File \u001b[1;32m~\\AppData\\Roaming\\jupyterlab-desktop\\jlab_server\\lib\\site-packages\\redis\\connection.py:625\u001b[0m, in \u001b[0;36mConnection.connect.<locals>.<lambda>\u001b[1;34m()\u001b[0m\n\u001b[0;32m    623\u001b[0m \u001b[38;5;28;01mtry\u001b[39;00m:\n\u001b[0;32m    624\u001b[0m     sock \u001b[38;5;241m=\u001b[39m \u001b[38;5;28mself\u001b[39m\u001b[38;5;241m.\u001b[39mretry\u001b[38;5;241m.\u001b[39mcall_with_retry(\n\u001b[1;32m--> 625\u001b[0m         \u001b[38;5;28;01mlambda\u001b[39;00m: \u001b[38;5;28;43mself\u001b[39;49m\u001b[38;5;241;43m.\u001b[39;49m\u001b[43m_connect\u001b[49m\u001b[43m(\u001b[49m\u001b[43m)\u001b[49m, \u001b[38;5;28;01mlambda\u001b[39;00m error: \u001b[38;5;28mself\u001b[39m\u001b[38;5;241m.\u001b[39mdisconnect(error)\n\u001b[0;32m    626\u001b[0m     )\n\u001b[0;32m    627\u001b[0m \u001b[38;5;28;01mexcept\u001b[39;00m socket\u001b[38;5;241m.\u001b[39mtimeout:\n",
      "File \u001b[1;32m~\\AppData\\Roaming\\jupyterlab-desktop\\jlab_server\\lib\\site-packages\\redis\\connection.py:690\u001b[0m, in \u001b[0;36mConnection._connect\u001b[1;34m(self)\u001b[0m\n\u001b[0;32m    689\u001b[0m \u001b[38;5;28;01mif\u001b[39;00m err \u001b[38;5;129;01mis\u001b[39;00m \u001b[38;5;129;01mnot\u001b[39;00m \u001b[38;5;28;01mNone\u001b[39;00m:\n\u001b[1;32m--> 690\u001b[0m     \u001b[38;5;28;01mraise\u001b[39;00m err\n\u001b[0;32m    691\u001b[0m \u001b[38;5;28;01mraise\u001b[39;00m \u001b[38;5;167;01mOSError\u001b[39;00m(\u001b[38;5;124m\"\u001b[39m\u001b[38;5;124msocket.getaddrinfo returned an empty list\u001b[39m\u001b[38;5;124m\"\u001b[39m)\n",
      "File \u001b[1;32m~\\AppData\\Roaming\\jupyterlab-desktop\\jlab_server\\lib\\site-packages\\redis\\connection.py:678\u001b[0m, in \u001b[0;36mConnection._connect\u001b[1;34m(self)\u001b[0m\n\u001b[0;32m    677\u001b[0m \u001b[38;5;66;03m# connect\u001b[39;00m\n\u001b[1;32m--> 678\u001b[0m \u001b[43msock\u001b[49m\u001b[38;5;241;43m.\u001b[39;49m\u001b[43mconnect\u001b[49m\u001b[43m(\u001b[49m\u001b[43msocket_address\u001b[49m\u001b[43m)\u001b[49m\n\u001b[0;32m    680\u001b[0m \u001b[38;5;66;03m# set the socket_timeout now that we're connected\u001b[39;00m\n",
      "\u001b[1;31mConnectionRefusedError\u001b[0m: [WinError 10061] Подключение не установлено, т.к. конечный компьютер отверг запрос на подключение",
      "\nDuring handling of the above exception, another exception occurred:\n",
      "\u001b[1;31mConnectionError\u001b[0m                           Traceback (most recent call last)",
      "Cell \u001b[1;32mIn[7], line 1\u001b[0m\n\u001b[1;32m----> 1\u001b[0m \u001b[38;5;28;01mfor\u001b[39;00m key \u001b[38;5;129;01min\u001b[39;00m r\u001b[38;5;241m.\u001b[39mscan_iter(\u001b[38;5;124m\"\u001b[39m\u001b[38;5;124mbase*\u001b[39m\u001b[38;5;124m\"\u001b[39m):\n\u001b[0;32m      2\u001b[0m     \u001b[38;5;28mprint\u001b[39m(key)\n",
      "File \u001b[1;32m~\\AppData\\Roaming\\jupyterlab-desktop\\jlab_server\\lib\\site-packages\\redis\\commands\\core.py:3003\u001b[0m, in \u001b[0;36mScanCommands.scan_iter\u001b[1;34m(self, match, count, _type, **kwargs)\u001b[0m\n\u001b[0;32m   3001\u001b[0m cursor \u001b[38;5;241m=\u001b[39m \u001b[38;5;124m\"\u001b[39m\u001b[38;5;124m0\u001b[39m\u001b[38;5;124m\"\u001b[39m\n\u001b[0;32m   3002\u001b[0m \u001b[38;5;28;01mwhile\u001b[39;00m cursor \u001b[38;5;241m!=\u001b[39m \u001b[38;5;241m0\u001b[39m:\n\u001b[1;32m-> 3003\u001b[0m     cursor, data \u001b[38;5;241m=\u001b[39m \u001b[38;5;28;43mself\u001b[39;49m\u001b[38;5;241;43m.\u001b[39;49m\u001b[43mscan\u001b[49m\u001b[43m(\u001b[49m\n\u001b[0;32m   3004\u001b[0m \u001b[43m        \u001b[49m\u001b[43mcursor\u001b[49m\u001b[38;5;241;43m=\u001b[39;49m\u001b[43mcursor\u001b[49m\u001b[43m,\u001b[49m\u001b[43m \u001b[49m\u001b[43mmatch\u001b[49m\u001b[38;5;241;43m=\u001b[39;49m\u001b[43mmatch\u001b[49m\u001b[43m,\u001b[49m\u001b[43m \u001b[49m\u001b[43mcount\u001b[49m\u001b[38;5;241;43m=\u001b[39;49m\u001b[43mcount\u001b[49m\u001b[43m,\u001b[49m\u001b[43m \u001b[49m\u001b[43m_type\u001b[49m\u001b[38;5;241;43m=\u001b[39;49m\u001b[43m_type\u001b[49m\u001b[43m,\u001b[49m\u001b[43m \u001b[49m\u001b[38;5;241;43m*\u001b[39;49m\u001b[38;5;241;43m*\u001b[39;49m\u001b[43mkwargs\u001b[49m\n\u001b[0;32m   3005\u001b[0m \u001b[43m    \u001b[49m\u001b[43m)\u001b[49m\n\u001b[0;32m   3006\u001b[0m     \u001b[38;5;28;01myield from\u001b[39;00m data\n",
      "File \u001b[1;32m~\\AppData\\Roaming\\jupyterlab-desktop\\jlab_server\\lib\\site-packages\\redis\\commands\\core.py:2978\u001b[0m, in \u001b[0;36mScanCommands.scan\u001b[1;34m(self, cursor, match, count, _type, **kwargs)\u001b[0m\n\u001b[0;32m   2976\u001b[0m \u001b[38;5;28;01mif\u001b[39;00m _type \u001b[38;5;129;01mis\u001b[39;00m \u001b[38;5;129;01mnot\u001b[39;00m \u001b[38;5;28;01mNone\u001b[39;00m:\n\u001b[0;32m   2977\u001b[0m     pieces\u001b[38;5;241m.\u001b[39mextend([\u001b[38;5;124mb\u001b[39m\u001b[38;5;124m\"\u001b[39m\u001b[38;5;124mTYPE\u001b[39m\u001b[38;5;124m\"\u001b[39m, _type])\n\u001b[1;32m-> 2978\u001b[0m \u001b[38;5;28;01mreturn\u001b[39;00m \u001b[38;5;28;43mself\u001b[39;49m\u001b[38;5;241;43m.\u001b[39;49m\u001b[43mexecute_command\u001b[49m\u001b[43m(\u001b[49m\u001b[38;5;124;43m\"\u001b[39;49m\u001b[38;5;124;43mSCAN\u001b[39;49m\u001b[38;5;124;43m\"\u001b[39;49m\u001b[43m,\u001b[49m\u001b[43m \u001b[49m\u001b[38;5;241;43m*\u001b[39;49m\u001b[43mpieces\u001b[49m\u001b[43m,\u001b[49m\u001b[43m \u001b[49m\u001b[38;5;241;43m*\u001b[39;49m\u001b[38;5;241;43m*\u001b[39;49m\u001b[43mkwargs\u001b[49m\u001b[43m)\u001b[49m\n",
      "File \u001b[1;32m~\\AppData\\Roaming\\jupyterlab-desktop\\jlab_server\\lib\\site-packages\\redis\\client.py:1255\u001b[0m, in \u001b[0;36mRedis.execute_command\u001b[1;34m(self, *args, **options)\u001b[0m\n\u001b[0;32m   1253\u001b[0m pool \u001b[38;5;241m=\u001b[39m \u001b[38;5;28mself\u001b[39m\u001b[38;5;241m.\u001b[39mconnection_pool\n\u001b[0;32m   1254\u001b[0m command_name \u001b[38;5;241m=\u001b[39m args[\u001b[38;5;241m0\u001b[39m]\n\u001b[1;32m-> 1255\u001b[0m conn \u001b[38;5;241m=\u001b[39m \u001b[38;5;28mself\u001b[39m\u001b[38;5;241m.\u001b[39mconnection \u001b[38;5;129;01mor\u001b[39;00m \u001b[43mpool\u001b[49m\u001b[38;5;241;43m.\u001b[39;49m\u001b[43mget_connection\u001b[49m\u001b[43m(\u001b[49m\u001b[43mcommand_name\u001b[49m\u001b[43m,\u001b[49m\u001b[43m \u001b[49m\u001b[38;5;241;43m*\u001b[39;49m\u001b[38;5;241;43m*\u001b[39;49m\u001b[43moptions\u001b[49m\u001b[43m)\u001b[49m\n\u001b[0;32m   1257\u001b[0m \u001b[38;5;28;01mtry\u001b[39;00m:\n\u001b[0;32m   1258\u001b[0m     \u001b[38;5;28;01mreturn\u001b[39;00m conn\u001b[38;5;241m.\u001b[39mretry\u001b[38;5;241m.\u001b[39mcall_with_retry(\n\u001b[0;32m   1259\u001b[0m         \u001b[38;5;28;01mlambda\u001b[39;00m: \u001b[38;5;28mself\u001b[39m\u001b[38;5;241m.\u001b[39m_send_command_parse_response(\n\u001b[0;32m   1260\u001b[0m             conn, command_name, \u001b[38;5;241m*\u001b[39margs, \u001b[38;5;241m*\u001b[39m\u001b[38;5;241m*\u001b[39moptions\n\u001b[0;32m   1261\u001b[0m         ),\n\u001b[0;32m   1262\u001b[0m         \u001b[38;5;28;01mlambda\u001b[39;00m error: \u001b[38;5;28mself\u001b[39m\u001b[38;5;241m.\u001b[39m_disconnect_raise(conn, error),\n\u001b[0;32m   1263\u001b[0m     )\n",
      "File \u001b[1;32m~\\AppData\\Roaming\\jupyterlab-desktop\\jlab_server\\lib\\site-packages\\redis\\connection.py:1427\u001b[0m, in \u001b[0;36mConnectionPool.get_connection\u001b[1;34m(self, command_name, *keys, **options)\u001b[0m\n\u001b[0;32m   1423\u001b[0m     \u001b[38;5;28mself\u001b[39m\u001b[38;5;241m.\u001b[39m_in_use_connections\u001b[38;5;241m.\u001b[39madd(connection)\n\u001b[0;32m   1425\u001b[0m \u001b[38;5;28;01mtry\u001b[39;00m:\n\u001b[0;32m   1426\u001b[0m     \u001b[38;5;66;03m# ensure this connection is connected to Redis\u001b[39;00m\n\u001b[1;32m-> 1427\u001b[0m     \u001b[43mconnection\u001b[49m\u001b[38;5;241;43m.\u001b[39;49m\u001b[43mconnect\u001b[49m\u001b[43m(\u001b[49m\u001b[43m)\u001b[49m\n\u001b[0;32m   1428\u001b[0m     \u001b[38;5;66;03m# connections that the pool provides should be ready to send\u001b[39;00m\n\u001b[0;32m   1429\u001b[0m     \u001b[38;5;66;03m# a command. if not, the connection was either returned to the\u001b[39;00m\n\u001b[0;32m   1430\u001b[0m     \u001b[38;5;66;03m# pool before all data has been read or the socket has been\u001b[39;00m\n\u001b[0;32m   1431\u001b[0m     \u001b[38;5;66;03m# closed. either way, reconnect and verify everything is good.\u001b[39;00m\n\u001b[0;32m   1432\u001b[0m     \u001b[38;5;28;01mtry\u001b[39;00m:\n",
      "File \u001b[1;32m~\\AppData\\Roaming\\jupyterlab-desktop\\jlab_server\\lib\\site-packages\\redis\\connection.py:630\u001b[0m, in \u001b[0;36mConnection.connect\u001b[1;34m(self)\u001b[0m\n\u001b[0;32m    628\u001b[0m     \u001b[38;5;28;01mraise\u001b[39;00m \u001b[38;5;167;01mTimeoutError\u001b[39;00m(\u001b[38;5;124m\"\u001b[39m\u001b[38;5;124mTimeout connecting to server\u001b[39m\u001b[38;5;124m\"\u001b[39m)\n\u001b[0;32m    629\u001b[0m \u001b[38;5;28;01mexcept\u001b[39;00m \u001b[38;5;167;01mOSError\u001b[39;00m \u001b[38;5;28;01mas\u001b[39;00m e:\n\u001b[1;32m--> 630\u001b[0m     \u001b[38;5;28;01mraise\u001b[39;00m \u001b[38;5;167;01mConnectionError\u001b[39;00m(\u001b[38;5;28mself\u001b[39m\u001b[38;5;241m.\u001b[39m_error_message(e))\n\u001b[0;32m    632\u001b[0m \u001b[38;5;28mself\u001b[39m\u001b[38;5;241m.\u001b[39m_sock \u001b[38;5;241m=\u001b[39m sock\n\u001b[0;32m    633\u001b[0m \u001b[38;5;28;01mtry\u001b[39;00m:\n",
      "\u001b[1;31mConnectionError\u001b[0m: Error 10061 connecting to 127.0.0.1:6379. Подключение не установлено, т.к. конечный компьютер отверг запрос на подключение."
     ]
    }
   ],
   "source": [
    "for key in r.scan_iter(\"base*\"):\n",
    "    print(key)"
   ]
  },
  {
   "cell_type": "code",
   "execution_count": 6,
   "id": "9f7b170d-85f3-454e-9f6e-2e10507504ba",
   "metadata": {},
   "outputs": [
    {
     "ename": "ConnectionError",
     "evalue": "Error 10061 connecting to 127.0.0.1:6379. Подключение не установлено, т.к. конечный компьютер отверг запрос на подключение.",
     "output_type": "error",
     "traceback": [
      "\u001b[1;31m---------------------------------------------------------------------------\u001b[0m",
      "\u001b[1;31mConnectionRefusedError\u001b[0m                    Traceback (most recent call last)",
      "File \u001b[1;32m~\\AppData\\Roaming\\jupyterlab-desktop\\jlab_server\\lib\\site-packages\\redis\\connection.py:624\u001b[0m, in \u001b[0;36mConnection.connect\u001b[1;34m(self)\u001b[0m\n\u001b[0;32m    623\u001b[0m \u001b[38;5;28;01mtry\u001b[39;00m:\n\u001b[1;32m--> 624\u001b[0m     sock \u001b[38;5;241m=\u001b[39m \u001b[38;5;28;43mself\u001b[39;49m\u001b[38;5;241;43m.\u001b[39;49m\u001b[43mretry\u001b[49m\u001b[38;5;241;43m.\u001b[39;49m\u001b[43mcall_with_retry\u001b[49m\u001b[43m(\u001b[49m\n\u001b[0;32m    625\u001b[0m \u001b[43m        \u001b[49m\u001b[38;5;28;43;01mlambda\u001b[39;49;00m\u001b[43m:\u001b[49m\u001b[43m \u001b[49m\u001b[38;5;28;43mself\u001b[39;49m\u001b[38;5;241;43m.\u001b[39;49m\u001b[43m_connect\u001b[49m\u001b[43m(\u001b[49m\u001b[43m)\u001b[49m\u001b[43m,\u001b[49m\u001b[43m \u001b[49m\u001b[38;5;28;43;01mlambda\u001b[39;49;00m\u001b[43m \u001b[49m\u001b[43merror\u001b[49m\u001b[43m:\u001b[49m\u001b[43m \u001b[49m\u001b[38;5;28;43mself\u001b[39;49m\u001b[38;5;241;43m.\u001b[39;49m\u001b[43mdisconnect\u001b[49m\u001b[43m(\u001b[49m\u001b[43merror\u001b[49m\u001b[43m)\u001b[49m\n\u001b[0;32m    626\u001b[0m \u001b[43m    \u001b[49m\u001b[43m)\u001b[49m\n\u001b[0;32m    627\u001b[0m \u001b[38;5;28;01mexcept\u001b[39;00m socket\u001b[38;5;241m.\u001b[39mtimeout:\n",
      "File \u001b[1;32m~\\AppData\\Roaming\\jupyterlab-desktop\\jlab_server\\lib\\site-packages\\redis\\retry.py:46\u001b[0m, in \u001b[0;36mRetry.call_with_retry\u001b[1;34m(self, do, fail)\u001b[0m\n\u001b[0;32m     45\u001b[0m \u001b[38;5;28;01mtry\u001b[39;00m:\n\u001b[1;32m---> 46\u001b[0m     \u001b[38;5;28;01mreturn\u001b[39;00m \u001b[43mdo\u001b[49m\u001b[43m(\u001b[49m\u001b[43m)\u001b[49m\n\u001b[0;32m     47\u001b[0m \u001b[38;5;28;01mexcept\u001b[39;00m \u001b[38;5;28mself\u001b[39m\u001b[38;5;241m.\u001b[39m_supported_errors \u001b[38;5;28;01mas\u001b[39;00m error:\n",
      "File \u001b[1;32m~\\AppData\\Roaming\\jupyterlab-desktop\\jlab_server\\lib\\site-packages\\redis\\connection.py:625\u001b[0m, in \u001b[0;36mConnection.connect.<locals>.<lambda>\u001b[1;34m()\u001b[0m\n\u001b[0;32m    623\u001b[0m \u001b[38;5;28;01mtry\u001b[39;00m:\n\u001b[0;32m    624\u001b[0m     sock \u001b[38;5;241m=\u001b[39m \u001b[38;5;28mself\u001b[39m\u001b[38;5;241m.\u001b[39mretry\u001b[38;5;241m.\u001b[39mcall_with_retry(\n\u001b[1;32m--> 625\u001b[0m         \u001b[38;5;28;01mlambda\u001b[39;00m: \u001b[38;5;28;43mself\u001b[39;49m\u001b[38;5;241;43m.\u001b[39;49m\u001b[43m_connect\u001b[49m\u001b[43m(\u001b[49m\u001b[43m)\u001b[49m, \u001b[38;5;28;01mlambda\u001b[39;00m error: \u001b[38;5;28mself\u001b[39m\u001b[38;5;241m.\u001b[39mdisconnect(error)\n\u001b[0;32m    626\u001b[0m     )\n\u001b[0;32m    627\u001b[0m \u001b[38;5;28;01mexcept\u001b[39;00m socket\u001b[38;5;241m.\u001b[39mtimeout:\n",
      "File \u001b[1;32m~\\AppData\\Roaming\\jupyterlab-desktop\\jlab_server\\lib\\site-packages\\redis\\connection.py:690\u001b[0m, in \u001b[0;36mConnection._connect\u001b[1;34m(self)\u001b[0m\n\u001b[0;32m    689\u001b[0m \u001b[38;5;28;01mif\u001b[39;00m err \u001b[38;5;129;01mis\u001b[39;00m \u001b[38;5;129;01mnot\u001b[39;00m \u001b[38;5;28;01mNone\u001b[39;00m:\n\u001b[1;32m--> 690\u001b[0m     \u001b[38;5;28;01mraise\u001b[39;00m err\n\u001b[0;32m    691\u001b[0m \u001b[38;5;28;01mraise\u001b[39;00m \u001b[38;5;167;01mOSError\u001b[39;00m(\u001b[38;5;124m\"\u001b[39m\u001b[38;5;124msocket.getaddrinfo returned an empty list\u001b[39m\u001b[38;5;124m\"\u001b[39m)\n",
      "File \u001b[1;32m~\\AppData\\Roaming\\jupyterlab-desktop\\jlab_server\\lib\\site-packages\\redis\\connection.py:678\u001b[0m, in \u001b[0;36mConnection._connect\u001b[1;34m(self)\u001b[0m\n\u001b[0;32m    677\u001b[0m \u001b[38;5;66;03m# connect\u001b[39;00m\n\u001b[1;32m--> 678\u001b[0m \u001b[43msock\u001b[49m\u001b[38;5;241;43m.\u001b[39;49m\u001b[43mconnect\u001b[49m\u001b[43m(\u001b[49m\u001b[43msocket_address\u001b[49m\u001b[43m)\u001b[49m\n\u001b[0;32m    680\u001b[0m \u001b[38;5;66;03m# set the socket_timeout now that we're connected\u001b[39;00m\n",
      "\u001b[1;31mConnectionRefusedError\u001b[0m: [WinError 10061] Подключение не установлено, т.к. конечный компьютер отверг запрос на подключение",
      "\nDuring handling of the above exception, another exception occurred:\n",
      "\u001b[1;31mConnectionError\u001b[0m                           Traceback (most recent call last)",
      "Cell \u001b[1;32mIn[6], line 1\u001b[0m\n\u001b[1;32m----> 1\u001b[0m df\u001b[38;5;241m=\u001b[39m \u001b[43mget_cache_on_key\u001b[49m\u001b[43m(\u001b[49m\u001b[38;5;124;43m\"\u001b[39;49m\u001b[38;5;124;43mbase1.test2.var1\u001b[39;49m\u001b[38;5;124;43m\"\u001b[39;49m\u001b[43m)\u001b[49m\n",
      "Cell \u001b[1;32mIn[5], line 4\u001b[0m, in \u001b[0;36mget_cache_on_key\u001b[1;34m(key)\u001b[0m\n\u001b[0;32m      3\u001b[0m \u001b[38;5;28;01mdef\u001b[39;00m \u001b[38;5;21mget_cache_on_key\u001b[39m(key):\n\u001b[1;32m----> 4\u001b[0m     buff \u001b[38;5;241m=\u001b[39m \u001b[43mr\u001b[49m\u001b[38;5;241;43m.\u001b[39;49m\u001b[43mget\u001b[49m\u001b[43m(\u001b[49m\u001b[43mkey\u001b[49m\u001b[43m)\u001b[49m\n\u001b[0;32m      5\u001b[0m     \u001b[38;5;28;01mif\u001b[39;00m buff:\n\u001b[0;32m      6\u001b[0m         \u001b[38;5;28;01mreturn\u001b[39;00m pkl\u001b[38;5;241m.\u001b[39mloads(buff)\n",
      "File \u001b[1;32m~\\AppData\\Roaming\\jupyterlab-desktop\\jlab_server\\lib\\site-packages\\redis\\commands\\core.py:1790\u001b[0m, in \u001b[0;36mBasicKeyCommands.get\u001b[1;34m(self, name)\u001b[0m\n\u001b[0;32m   1784\u001b[0m \u001b[38;5;28;01mdef\u001b[39;00m \u001b[38;5;21mget\u001b[39m(\u001b[38;5;28mself\u001b[39m, name: KeyT) \u001b[38;5;241m-\u001b[39m\u001b[38;5;241m>\u001b[39m ResponseT:\n\u001b[0;32m   1785\u001b[0m     \u001b[38;5;124;03m\"\"\"\u001b[39;00m\n\u001b[0;32m   1786\u001b[0m \u001b[38;5;124;03m    Return the value at key ``name``, or None if the key doesn't exist\u001b[39;00m\n\u001b[0;32m   1787\u001b[0m \n\u001b[0;32m   1788\u001b[0m \u001b[38;5;124;03m    For more information see https://redis.io/commands/get\u001b[39;00m\n\u001b[0;32m   1789\u001b[0m \u001b[38;5;124;03m    \"\"\"\u001b[39;00m\n\u001b[1;32m-> 1790\u001b[0m     \u001b[38;5;28;01mreturn\u001b[39;00m \u001b[38;5;28;43mself\u001b[39;49m\u001b[38;5;241;43m.\u001b[39;49m\u001b[43mexecute_command\u001b[49m\u001b[43m(\u001b[49m\u001b[38;5;124;43m\"\u001b[39;49m\u001b[38;5;124;43mGET\u001b[39;49m\u001b[38;5;124;43m\"\u001b[39;49m\u001b[43m,\u001b[49m\u001b[43m \u001b[49m\u001b[43mname\u001b[49m\u001b[43m)\u001b[49m\n",
      "File \u001b[1;32m~\\AppData\\Roaming\\jupyterlab-desktop\\jlab_server\\lib\\site-packages\\redis\\client.py:1255\u001b[0m, in \u001b[0;36mRedis.execute_command\u001b[1;34m(self, *args, **options)\u001b[0m\n\u001b[0;32m   1253\u001b[0m pool \u001b[38;5;241m=\u001b[39m \u001b[38;5;28mself\u001b[39m\u001b[38;5;241m.\u001b[39mconnection_pool\n\u001b[0;32m   1254\u001b[0m command_name \u001b[38;5;241m=\u001b[39m args[\u001b[38;5;241m0\u001b[39m]\n\u001b[1;32m-> 1255\u001b[0m conn \u001b[38;5;241m=\u001b[39m \u001b[38;5;28mself\u001b[39m\u001b[38;5;241m.\u001b[39mconnection \u001b[38;5;129;01mor\u001b[39;00m \u001b[43mpool\u001b[49m\u001b[38;5;241;43m.\u001b[39;49m\u001b[43mget_connection\u001b[49m\u001b[43m(\u001b[49m\u001b[43mcommand_name\u001b[49m\u001b[43m,\u001b[49m\u001b[43m \u001b[49m\u001b[38;5;241;43m*\u001b[39;49m\u001b[38;5;241;43m*\u001b[39;49m\u001b[43moptions\u001b[49m\u001b[43m)\u001b[49m\n\u001b[0;32m   1257\u001b[0m \u001b[38;5;28;01mtry\u001b[39;00m:\n\u001b[0;32m   1258\u001b[0m     \u001b[38;5;28;01mreturn\u001b[39;00m conn\u001b[38;5;241m.\u001b[39mretry\u001b[38;5;241m.\u001b[39mcall_with_retry(\n\u001b[0;32m   1259\u001b[0m         \u001b[38;5;28;01mlambda\u001b[39;00m: \u001b[38;5;28mself\u001b[39m\u001b[38;5;241m.\u001b[39m_send_command_parse_response(\n\u001b[0;32m   1260\u001b[0m             conn, command_name, \u001b[38;5;241m*\u001b[39margs, \u001b[38;5;241m*\u001b[39m\u001b[38;5;241m*\u001b[39moptions\n\u001b[0;32m   1261\u001b[0m         ),\n\u001b[0;32m   1262\u001b[0m         \u001b[38;5;28;01mlambda\u001b[39;00m error: \u001b[38;5;28mself\u001b[39m\u001b[38;5;241m.\u001b[39m_disconnect_raise(conn, error),\n\u001b[0;32m   1263\u001b[0m     )\n",
      "File \u001b[1;32m~\\AppData\\Roaming\\jupyterlab-desktop\\jlab_server\\lib\\site-packages\\redis\\connection.py:1427\u001b[0m, in \u001b[0;36mConnectionPool.get_connection\u001b[1;34m(self, command_name, *keys, **options)\u001b[0m\n\u001b[0;32m   1423\u001b[0m     \u001b[38;5;28mself\u001b[39m\u001b[38;5;241m.\u001b[39m_in_use_connections\u001b[38;5;241m.\u001b[39madd(connection)\n\u001b[0;32m   1425\u001b[0m \u001b[38;5;28;01mtry\u001b[39;00m:\n\u001b[0;32m   1426\u001b[0m     \u001b[38;5;66;03m# ensure this connection is connected to Redis\u001b[39;00m\n\u001b[1;32m-> 1427\u001b[0m     \u001b[43mconnection\u001b[49m\u001b[38;5;241;43m.\u001b[39;49m\u001b[43mconnect\u001b[49m\u001b[43m(\u001b[49m\u001b[43m)\u001b[49m\n\u001b[0;32m   1428\u001b[0m     \u001b[38;5;66;03m# connections that the pool provides should be ready to send\u001b[39;00m\n\u001b[0;32m   1429\u001b[0m     \u001b[38;5;66;03m# a command. if not, the connection was either returned to the\u001b[39;00m\n\u001b[0;32m   1430\u001b[0m     \u001b[38;5;66;03m# pool before all data has been read or the socket has been\u001b[39;00m\n\u001b[0;32m   1431\u001b[0m     \u001b[38;5;66;03m# closed. either way, reconnect and verify everything is good.\u001b[39;00m\n\u001b[0;32m   1432\u001b[0m     \u001b[38;5;28;01mtry\u001b[39;00m:\n",
      "File \u001b[1;32m~\\AppData\\Roaming\\jupyterlab-desktop\\jlab_server\\lib\\site-packages\\redis\\connection.py:630\u001b[0m, in \u001b[0;36mConnection.connect\u001b[1;34m(self)\u001b[0m\n\u001b[0;32m    628\u001b[0m     \u001b[38;5;28;01mraise\u001b[39;00m \u001b[38;5;167;01mTimeoutError\u001b[39;00m(\u001b[38;5;124m\"\u001b[39m\u001b[38;5;124mTimeout connecting to server\u001b[39m\u001b[38;5;124m\"\u001b[39m)\n\u001b[0;32m    629\u001b[0m \u001b[38;5;28;01mexcept\u001b[39;00m \u001b[38;5;167;01mOSError\u001b[39;00m \u001b[38;5;28;01mas\u001b[39;00m e:\n\u001b[1;32m--> 630\u001b[0m     \u001b[38;5;28;01mraise\u001b[39;00m \u001b[38;5;167;01mConnectionError\u001b[39;00m(\u001b[38;5;28mself\u001b[39m\u001b[38;5;241m.\u001b[39m_error_message(e))\n\u001b[0;32m    632\u001b[0m \u001b[38;5;28mself\u001b[39m\u001b[38;5;241m.\u001b[39m_sock \u001b[38;5;241m=\u001b[39m sock\n\u001b[0;32m    633\u001b[0m \u001b[38;5;28;01mtry\u001b[39;00m:\n",
      "\u001b[1;31mConnectionError\u001b[0m: Error 10061 connecting to 127.0.0.1:6379. Подключение не установлено, т.к. конечный компьютер отверг запрос на подключение."
     ]
    }
   ],
   "source": [
    "df= get_cache_on_key(\"base1.test2.var1\")"
   ]
  },
  {
   "cell_type": "code",
   "execution_count": null,
   "id": "bba10e25-9550-432d-9428-03328cfa4b05",
   "metadata": {},
   "outputs": [],
   "source": []
  }
 ],
 "metadata": {
  "kernelspec": {
   "display_name": "Python 3 (ipykernel)",
   "language": "python",
   "name": "python3"
  },
  "language_info": {
   "codemirror_mode": {
    "name": "ipython",
    "version": 3
   },
   "file_extension": ".py",
   "mimetype": "text/x-python",
   "name": "python",
   "nbconvert_exporter": "python",
   "pygments_lexer": "ipython3",
   "version": "3.8.15"
  }
 },
 "nbformat": 4,
 "nbformat_minor": 5
}
